2020-05-02 18:39:32,399 ERROR: Exception on /reset_password_request [POST] [in /home/obu/microblog/venv/lib/python3.7/site-packages/flask/app.py:1892]
Traceback (most recent call last):
  File "/home/obu/microblog/venv/lib/python3.7/site-packages/flask/app.py", line 2447, in wsgi_app
    response = self.full_dispatch_request()
  File "/home/obu/microblog/venv/lib/python3.7/site-packages/flask/app.py", line 1952, in full_dispatch_request
    rv = self.handle_user_exception(e)
  File "/home/obu/microblog/venv/lib/python3.7/site-packages/flask/app.py", line 1821, in handle_user_exception
    reraise(exc_type, exc_value, tb)
  File "/home/obu/microblog/venv/lib/python3.7/site-packages/flask/_compat.py", line 39, in reraise
    raise value
  File "/home/obu/microblog/venv/lib/python3.7/site-packages/flask/app.py", line 1950, in full_dispatch_request
    rv = self.dispatch_request()
  File "/home/obu/microblog/venv/lib/python3.7/site-packages/flask/app.py", line 1936, in dispatch_request
    return self.view_functions[rule.endpoint](**req.view_args)
  File "/home/obu/microblog/app/routes.py", line 151, in reset_password_request
    send_password_reset_email(user)
  File "/home/obu/microblog/app/email.py", line 11, in send_password_reset_email
    token = user.get_reset_password_token()
  File "/home/obu/microblog/app/models.py", line 60, in get_reset_password_token
    return jwt.encode(
NameError: name 'jwt' is not defined
2020-05-02 18:42:02,713 INFO: Microblog startup [in /home/obu/microblog/app/__init__.py:46]
2020-05-02 18:42:14,291 ERROR: Exception on /reset_password_request [POST] [in /home/obu/microblog/venv/lib/python3.7/site-packages/flask/app.py:1892]
Traceback (most recent call last):
  File "/home/obu/microblog/venv/lib/python3.7/site-packages/flask/app.py", line 2447, in wsgi_app
    response = self.full_dispatch_request()
  File "/home/obu/microblog/venv/lib/python3.7/site-packages/flask/app.py", line 1952, in full_dispatch_request
    rv = self.handle_user_exception(e)
  File "/home/obu/microblog/venv/lib/python3.7/site-packages/flask/app.py", line 1821, in handle_user_exception
    reraise(exc_type, exc_value, tb)
  File "/home/obu/microblog/venv/lib/python3.7/site-packages/flask/_compat.py", line 39, in reraise
    raise value
  File "/home/obu/microblog/venv/lib/python3.7/site-packages/flask/app.py", line 1950, in full_dispatch_request
    rv = self.dispatch_request()
  File "/home/obu/microblog/venv/lib/python3.7/site-packages/flask/app.py", line 1936, in dispatch_request
    return self.view_functions[rule.endpoint](**req.view_args)
  File "/home/obu/microblog/app/routes.py", line 151, in reset_password_request
    send_password_reset_email(user)
  File "/home/obu/microblog/app/email.py", line 11, in send_password_reset_email
    token = user.get_reset_password_token()
  File "/home/obu/microblog/app/models.py", line 62, in get_reset_password_token
    {'reset_password':self.id, 'exp':time()+expires_in},
NameError: name 'time' is not defined
2020-05-02 18:43:44,900 INFO: Microblog startup [in /home/obu/microblog/app/__init__.py:46]
2020-05-02 18:43:54,680 ERROR: Exception on /reset_password_request [POST] [in /home/obu/microblog/venv/lib/python3.7/site-packages/flask/app.py:1892]
Traceback (most recent call last):
  File "/home/obu/microblog/venv/lib/python3.7/site-packages/flask/app.py", line 2447, in wsgi_app
    response = self.full_dispatch_request()
  File "/home/obu/microblog/venv/lib/python3.7/site-packages/flask/app.py", line 1952, in full_dispatch_request
    rv = self.handle_user_exception(e)
  File "/home/obu/microblog/venv/lib/python3.7/site-packages/flask/app.py", line 1821, in handle_user_exception
    reraise(exc_type, exc_value, tb)
  File "/home/obu/microblog/venv/lib/python3.7/site-packages/flask/_compat.py", line 39, in reraise
    raise value
  File "/home/obu/microblog/venv/lib/python3.7/site-packages/flask/app.py", line 1950, in full_dispatch_request
    rv = self.dispatch_request()
  File "/home/obu/microblog/venv/lib/python3.7/site-packages/flask/app.py", line 1936, in dispatch_request
    return self.view_functions[rule.endpoint](**req.view_args)
  File "/home/obu/microblog/app/routes.py", line 151, in reset_password_request
    send_password_reset_email(user)
  File "/home/obu/microblog/app/email.py", line 11, in send_password_reset_email
    token = user.get_reset_password_token()
  File "/home/obu/microblog/app/models.py", line 64, in get_reset_password_token
    app.config['SECRET_KEY'],algorithms='HS256').decode('utf-8')
TypeError: encode() got an unexpected keyword argument 'algorithms'
2020-05-02 18:54:41,502 INFO: Microblog startup [in /home/obu/microblog/app/__init__.py:46]
2020-05-02 18:54:55,227 ERROR: Exception on /reset_password_request [POST] [in /home/obu/microblog/venv/lib/python3.7/site-packages/flask/app.py:1892]
Traceback (most recent call last):
  File "/home/obu/microblog/venv/lib/python3.7/site-packages/flask/app.py", line 2447, in wsgi_app
    response = self.full_dispatch_request()
  File "/home/obu/microblog/venv/lib/python3.7/site-packages/flask/app.py", line 1952, in full_dispatch_request
    rv = self.handle_user_exception(e)
  File "/home/obu/microblog/venv/lib/python3.7/site-packages/flask/app.py", line 1821, in handle_user_exception
    reraise(exc_type, exc_value, tb)
  File "/home/obu/microblog/venv/lib/python3.7/site-packages/flask/_compat.py", line 39, in reraise
    raise value
  File "/home/obu/microblog/venv/lib/python3.7/site-packages/flask/app.py", line 1950, in full_dispatch_request
    rv = self.dispatch_request()
  File "/home/obu/microblog/venv/lib/python3.7/site-packages/flask/app.py", line 1936, in dispatch_request
    return self.view_functions[rule.endpoint](**req.view_args)
  File "/home/obu/microblog/app/routes.py", line 151, in reset_password_request
    send_password_reset_email(user)
  File "/home/obu/microblog/app/email.py", line 17, in send_password_reset_email
    user=user,token=token))
TypeError: send_email() missing 1 required positional argument: 'recipients'
2020-05-02 18:57:14,413 INFO: Microblog startup [in /home/obu/microblog/app/__init__.py:46]
2020-05-02 19:02:50,662 INFO: Microblog startup [in /home/obu/microblog/app/__init__.py:46]
2020-05-02 22:08:43,512 INFO: Microblog startup [in /home/obu/microblog/app/__init__.py:48]
2020-05-02 22:08:49,537 ERROR: Exception on /login [GET] [in /home/obu/microblog/venv/lib/python3.7/site-packages/flask/app.py:1892]
Traceback (most recent call last):
  File "/home/obu/microblog/venv/lib/python3.7/site-packages/flask/app.py", line 2447, in wsgi_app
    response = self.full_dispatch_request()
  File "/home/obu/microblog/venv/lib/python3.7/site-packages/flask/app.py", line 1952, in full_dispatch_request
    rv = self.handle_user_exception(e)
  File "/home/obu/microblog/venv/lib/python3.7/site-packages/flask/app.py", line 1821, in handle_user_exception
    reraise(exc_type, exc_value, tb)
  File "/home/obu/microblog/venv/lib/python3.7/site-packages/flask/_compat.py", line 39, in reraise
    raise value
  File "/home/obu/microblog/venv/lib/python3.7/site-packages/flask/app.py", line 1950, in full_dispatch_request
    rv = self.dispatch_request()
  File "/home/obu/microblog/venv/lib/python3.7/site-packages/flask/app.py", line 1936, in dispatch_request
    return self.view_functions[rule.endpoint](**req.view_args)
  File "/home/obu/microblog/app/routes.py", line 49, in login
    return render_template('login.html', title ="Sign In", form=form)
  File "/home/obu/microblog/venv/lib/python3.7/site-packages/flask/templating.py", line 140, in render_template
    ctx.app,
  File "/home/obu/microblog/venv/lib/python3.7/site-packages/flask/templating.py", line 120, in _render
    rv = template.render(context)
  File "/home/obu/microblog/venv/lib/python3.7/site-packages/jinja2/environment.py", line 1090, in render
    self.environment.handle_exception()
  File "/home/obu/microblog/venv/lib/python3.7/site-packages/jinja2/environment.py", line 832, in handle_exception
    reraise(*rewrite_traceback_stack(source=source))
  File "/home/obu/microblog/venv/lib/python3.7/site-packages/jinja2/_compat.py", line 28, in reraise
    raise value.with_traceback(tb)
  File "/home/obu/microblog/app/templates/login.html", line 1, in top-level template code
    {% extends "base.html" %}
  File "/home/obu/microblog/venv/lib/python3.7/site-packages/jinja2/environment.py", line 832, in handle_exception
    reraise(*rewrite_traceback_stack(source=source))
  File "/home/obu/microblog/venv/lib/python3.7/site-packages/jinja2/_compat.py", line 28, in reraise
    raise value.with_traceback(tb)
  File "/home/obu/microblog/app/templates/base.html", line 41, in template
    {% blockcontent %}
jinja2.exceptions.TemplateSyntaxError: Encountered unknown tag 'blockcontent'.
2020-05-02 22:11:15,809 INFO: Microblog startup [in /home/obu/microblog/app/__init__.py:48]
